<?xml version="1.0"?>
<robot xmlns:xacro="http://www.ros.org/wiki/xacro" name="surgical_robot">
  <material name="blue"> <color rgba="0 0 0.8 1"/> </material>
  <material name="black"> <color rgba="0.1 0.1 0.1 1"/> </material>
  <material name="cyan"> <color rgba="0 1 1 1"/> </material>

  <link name="base_link">
    <visual>
      <geometry> <cylinder length="0.1" radius="0.1"/> </geometry>
      <material name="black"/>
    </visual>
  </link>

  <joint name="joint1" type="revolute">
    <parent link="base_link"/>
    <child link="link1"/>
    <origin xyz="0 0 0.05"/>
    <axis xyz="0 0 1"/>
    <limit lower="-3.14" upper="3.14" effort="10" velocity="1.0"/>
  </joint>

  <link name="link1">
    <visual>
      <geometry> <cylinder length="0.25" radius="0.05"/> </geometry>
      <origin xyz="0 0 0.125"/>
      <material name="blue"/>
    </visual>
  </link>

  <joint name="joint2" type="revolute">
    <parent link="link1"/>
    <child link="link2"/>
    <origin xyz="0 0 0.25"/>
    <axis xyz="0 1 0"/>
    <limit lower="-1.57" upper="1.57" effort="10" velocity="1.0"/>
  </joint>

  <link name="link2">
    <visual>
      <geometry> <cylinder length="0.2" radius="0.05"/> </geometry>
      <origin xyz="0 0 0.1"/>
      <material name="cyan"/>
    </visual>
  </link>
</robot>
